2025-04-06 22:27:50,381 ERROR: Exception on /login [POST] [in C:\pyProj\nir-assistant-ver2\venv\Lib\site-packages\flask\app.py:1414]
Traceback (most recent call last):
  File "C:\pyProj\nir-assistant-ver2\venv\Lib\site-packages\flask\app.py", line 2190, in wsgi_app
    response = self.full_dispatch_request()
               ^^^^^^^^^^^^^^^^^^^^^^^^^^^^
  File "C:\pyProj\nir-assistant-ver2\venv\Lib\site-packages\flask\app.py", line 1486, in full_dispatch_request
    rv = self.handle_user_exception(e)
         ^^^^^^^^^^^^^^^^^^^^^^^^^^^^^
  File "C:\pyProj\nir-assistant-ver2\venv\Lib\site-packages\flask\app.py", line 1484, in full_dispatch_request
    rv = self.dispatch_request()
         ^^^^^^^^^^^^^^^^^^^^^^^
  File "C:\pyProj\nir-assistant-ver2\venv\Lib\site-packages\flask\app.py", line 1469, in dispatch_request
    return self.ensure_sync(self.view_functions[rule.endpoint])(**view_args)
           ^^^^^^^^^^^^^^^^^^^^^^^^^^^^^^^^^^^^^^^^^^^^^^^^^^^^^^^^^^^^^^^^^
  File "C:\pyProj\nir-assistant-ver2\app\routes\auth.py", line 31, in login
    log_entry = LogEntry(
                ^^^^^^^^
NameError: name 'LogEntry' is not defined
2025-04-06 22:30:06,652 ERROR: Exception on /login [POST] [in C:\pyProj\nir-assistant-ver2\venv\Lib\site-packages\flask\app.py:1414]
Traceback (most recent call last):
  File "C:\pyProj\nir-assistant-ver2\venv\Lib\site-packages\flask\app.py", line 2190, in wsgi_app
    response = self.full_dispatch_request()
               ^^^^^^^^^^^^^^^^^^^^^^^^^^^^
  File "C:\pyProj\nir-assistant-ver2\venv\Lib\site-packages\flask\app.py", line 1486, in full_dispatch_request
    rv = self.handle_user_exception(e)
         ^^^^^^^^^^^^^^^^^^^^^^^^^^^^^
  File "C:\pyProj\nir-assistant-ver2\venv\Lib\site-packages\flask\app.py", line 1484, in full_dispatch_request
    rv = self.dispatch_request()
         ^^^^^^^^^^^^^^^^^^^^^^^
  File "C:\pyProj\nir-assistant-ver2\venv\Lib\site-packages\flask\app.py", line 1469, in dispatch_request
    return self.ensure_sync(self.view_functions[rule.endpoint])(**view_args)
           ^^^^^^^^^^^^^^^^^^^^^^^^^^^^^^^^^^^^^^^^^^^^^^^^^^^^^^^^^^^^^^^^^
  File "C:\pyProj\nir-assistant-ver2\app\routes\auth.py", line 31, in login
    log_entry = LogEntry(
                ^^^^^^^^
NameError: name 'LogEntry' is not defined
2025-04-06 22:45:45,778 ERROR: Exception on /login [POST] [in C:\pyProj\nir-assistant-ver2\venv\Lib\site-packages\flask\app.py:1414]
Traceback (most recent call last):
  File "C:\pyProj\nir-assistant-ver2\venv\Lib\site-packages\flask\app.py", line 2190, in wsgi_app
    response = self.full_dispatch_request()
               ^^^^^^^^^^^^^^^^^^^^^^^^^^^^
  File "C:\pyProj\nir-assistant-ver2\venv\Lib\site-packages\flask\app.py", line 1486, in full_dispatch_request
    rv = self.handle_user_exception(e)
         ^^^^^^^^^^^^^^^^^^^^^^^^^^^^^
  File "C:\pyProj\nir-assistant-ver2\venv\Lib\site-packages\flask\app.py", line 1484, in full_dispatch_request
    rv = self.dispatch_request()
         ^^^^^^^^^^^^^^^^^^^^^^^
  File "C:\pyProj\nir-assistant-ver2\venv\Lib\site-packages\flask\app.py", line 1469, in dispatch_request
    return self.ensure_sync(self.view_functions[rule.endpoint])(**view_args)
           ^^^^^^^^^^^^^^^^^^^^^^^^^^^^^^^^^^^^^^^^^^^^^^^^^^^^^^^^^^^^^^^^^
  File "C:\pyProj\nir-assistant-ver2\app\routes\auth.py", line 31, in login
    log_entry = LogEntry(
                ^^^^^^^^
NameError: name 'LogEntry' is not defined
2025-04-06 22:48:17,929 ERROR: Exception on /login [POST] [in C:\pyProj\nir-assistant-ver2\venv\Lib\site-packages\flask\app.py:1414]
Traceback (most recent call last):
  File "C:\pyProj\nir-assistant-ver2\venv\Lib\site-packages\flask\app.py", line 2190, in wsgi_app
    response = self.full_dispatch_request()
               ^^^^^^^^^^^^^^^^^^^^^^^^^^^^
  File "C:\pyProj\nir-assistant-ver2\venv\Lib\site-packages\flask\app.py", line 1486, in full_dispatch_request
    rv = self.handle_user_exception(e)
         ^^^^^^^^^^^^^^^^^^^^^^^^^^^^^
  File "C:\pyProj\nir-assistant-ver2\venv\Lib\site-packages\flask\app.py", line 1484, in full_dispatch_request
    rv = self.dispatch_request()
         ^^^^^^^^^^^^^^^^^^^^^^^
  File "C:\pyProj\nir-assistant-ver2\venv\Lib\site-packages\flask\app.py", line 1469, in dispatch_request
    return self.ensure_sync(self.view_functions[rule.endpoint])(**view_args)
           ^^^^^^^^^^^^^^^^^^^^^^^^^^^^^^^^^^^^^^^^^^^^^^^^^^^^^^^^^^^^^^^^^
  File "C:\pyProj\nir-assistant-ver2\app\routes\auth.py", line 31, in login
    log_entry = LogEntry(
                ^^^^^^^^
NameError: name 'LogEntry' is not defined
2025-04-06 23:20:08,575 INFO: NIR Assistant startup [in C:\pyProj\nir-assistant-ver2\app\__init__.py:72]
2025-04-06 23:28:41,462 INFO: NIR Assistant startup [in c:\pyProj\nir-assistant-ver2\app\__init__.py:72]
2025-04-06 23:28:42,193 INFO: NIR Assistant startup [in c:\pyProj\nir-assistant-ver2\app\__init__.py:72]
2025-04-06 23:29:09,048 INFO: NIR Assistant startup [in c:\pyProj\nir-assistant-ver2\app\__init__.py:72]
2025-04-06 23:29:09,808 INFO: NIR Assistant startup [in c:\pyProj\nir-assistant-ver2\app\__init__.py:72]
2025-04-06 23:48:14,158 INFO: NIR Assistant startup [in C:\pyProj\nir-assistant-ver2\app\__init__.py:72]
2025-04-06 23:53:40,210 INFO: NIR Assistant startup [in C:\pyProj\nir-assistant-ver2\app\__init__.py:72]
2025-04-07 00:15:44,571 INFO: NIR Assistant startup [in C:\pyProj\nir-assistant-ver2\app\__init__.py:72]
2025-04-07 00:24:49,138 INFO: NIR Assistant startup [in C:\pyProj\nir-assistant-ver2\app\__init__.py:72]
2025-04-07 00:32:41,655 INFO: NIR Assistant startup [in C:\pyProj\nir-assistant-ver2\app\__init__.py:72]
2025-04-07 00:36:43,216 INFO: NIR Assistant startup [in C:\pyProj\nir-assistant-ver2\app\__init__.py:72]
2025-04-07 00:41:20,724 INFO: NIR Assistant startup [in C:\pyProj\nir-assistant-ver2\app\__init__.py:72]
2025-04-07 14:07:26,059 INFO: NIR Assistant startup [in C:\Users\danil\AIdocAssistant\web\app\__init__.py:72]
2025-04-07 14:39:52,070 INFO: NIR Assistant startup [in C:\Users\danil\AIdocAssistant\web\app\__init__.py:72]
2025-04-07 14:40:09,214 INFO: NIR Assistant startup [in C:\Users\danil\AIdocAssistant\web\app\__init__.py:72]
2025-04-07 14:40:28,872 INFO: NIR Assistant startup [in C:\Users\danil\AIdocAssistant\web\app\__init__.py:72]
2025-04-07 14:41:01,947 INFO: NIR Assistant startup [in C:\Users\danil\AIdocAssistant\web\app\__init__.py:72]
2025-04-07 15:25:21,350 INFO: NIR Assistant startup [in C:\Users\danil\AIdocAssistant\web\app\__init__.py:72]
2025-04-07 15:25:21,365 INFO: NIR Assistant startup [in C:\Users\danil\AIdocAssistant\web\app\__init__.py:72]
2025-04-07 15:25:21,365 INFO: NIR Assistant startup [in C:\Users\danil\AIdocAssistant\web\app\__init__.py:72]
2025-04-07 15:25:22,211 INFO: NIR Assistant startup [in C:\Users\danil\AIdocAssistant\web\app\__init__.py:72]
2025-04-07 15:25:22,226 INFO: NIR Assistant startup [in C:\Users\danil\AIdocAssistant\web\app\__init__.py:72]
2025-04-07 15:25:22,226 INFO: NIR Assistant startup [in C:\Users\danil\AIdocAssistant\web\app\__init__.py:72]
2025-04-07 17:30:56,549 INFO: NIR Assistant startup [in C:\Users\danil\AIdocAssistant\web\app\__init__.py:72]
2025-04-07 17:31:51,505 ERROR: Exception on /2/section/2/edit [GET] [in C:\Users\danil\AIdocAssistant\venv\Lib\site-packages\flask\app.py:1414]
Traceback (most recent call last):
  File "C:\Users\danil\AIdocAssistant\venv\Lib\site-packages\flask\app.py", line 2190, in wsgi_app
    response = self.full_dispatch_request()
               ^^^^^^^^^^^^^^^^^^^^^^^^^^^^
  File "C:\Users\danil\AIdocAssistant\venv\Lib\site-packages\flask\app.py", line 1486, in full_dispatch_request
    rv = self.handle_user_exception(e)
         ^^^^^^^^^^^^^^^^^^^^^^^^^^^^^
  File "C:\Users\danil\AIdocAssistant\venv\Lib\site-packages\flask\app.py", line 1484, in full_dispatch_request
    rv = self.dispatch_request()
         ^^^^^^^^^^^^^^^^^^^^^^^
  File "C:\Users\danil\AIdocAssistant\venv\Lib\site-packages\flask\app.py", line 1469, in dispatch_request
    return self.ensure_sync(self.view_functions[rule.endpoint])(**view_args)
           ^^^^^^^^^^^^^^^^^^^^^^^^^^^^^^^^^^^^^^^^^^^^^^^^^^^^^^^^^^^^^^^^^
  File "C:\Users\danil\AIdocAssistant\venv\Lib\site-packages\flask_login\utils.py", line 290, in decorated_view
    return current_app.ensure_sync(func)(*args, **kwargs)
           ^^^^^^^^^^^^^^^^^^^^^^^^^^^^^^^^^^^^^^^^^^^^^^
  File "C:\Users\danil\AIdocAssistant\web\app\routes\documents.py", line 443, in edit_section
    return render_template('documents/section_form.html',
           ^^^^^^^^^^^^^^^^^^^^^^^^^^^^^^^^^^^^^^^^^^^^^^
  File "C:\Users\danil\AIdocAssistant\venv\Lib\site-packages\flask\templating.py", line 151, in render_template
    return _render(app, template, context)
           ^^^^^^^^^^^^^^^^^^^^^^^^^^^^^^^
  File "C:\Users\danil\AIdocAssistant\venv\Lib\site-packages\flask\templating.py", line 132, in _render
    rv = template.render(context)
         ^^^^^^^^^^^^^^^^^^^^^^^^
  File "C:\Users\danil\AIdocAssistant\venv\Lib\site-packages\jinja2\environment.py", line 1295, in render
    self.environment.handle_exception()
  File "C:\Users\danil\AIdocAssistant\venv\Lib\site-packages\jinja2\environment.py", line 942, in handle_exception
    raise rewrite_traceback_stack(source=source)
  File "C:\Users\danil\AIdocAssistant\web\app\templates\documents\section_form.html", line 1, in top-level template code
    {% extends "base.html" %}
  File "C:\Users\danil\AIdocAssistant\web\app\templates\base.html", line 95, in top-level template code
    {% block content %}{% endblock %}
    ^^^^^^^^^^^^^^^^^^^^^^^^^
  File "C:\Users\danil\AIdocAssistant\web\app\templates\documents\section_form.html", line 75, in block 'content'
    {% for section_item in document.template.sections %}
    ^^^^^^^^^^^^^^^^^^^^^^^^^
  File "C:\Users\danil\AIdocAssistant\venv\Lib\site-packages\jinja2\environment.py", line 490, in getattr
    return getattr(obj, attribute)
           ^^^^^^^^^^^^^^^^^^^^^^^
jinja2.exceptions.UndefinedError: 'app.models.DocumentApp object' has no attribute 'template'
