2025-04-07 12:59:16,967 ERROR: Exception on / [GET] [in C:\Users\danil\AIdocAssistant\venv\Lib\site-packages\flask\app.py:1414]
Traceback (most recent call last):
  File "C:\Users\danil\AIdocAssistant\venv\Lib\site-packages\sqlalchemy\orm\relationships.py", line 2437, in _determine_joins
    self.primaryjoin = join_condition(
                       ^^^^^^^^^^^^^^^
  File "C:\Users\danil\AIdocAssistant\venv\Lib\site-packages\sqlalchemy\sql\util.py", line 123, in join_condition
    return Join._join_condition(
           ^^^^^^^^^^^^^^^^^^^^^
  File "C:\Users\danil\AIdocAssistant\venv\Lib\site-packages\sqlalchemy\sql\selectable.py", line 1443, in _join_condition
    raise exc.NoForeignKeysError(
sqlalchemy.exc.NoForeignKeysError: Can't find any foreign key relationships between 'document_app' and 'document_block'.

The above exception was the direct cause of the following exception:

Traceback (most recent call last):
  File "C:\Users\danil\AIdocAssistant\venv\Lib\site-packages\flask\app.py", line 2190, in wsgi_app
    response = self.full_dispatch_request()
               ^^^^^^^^^^^^^^^^^^^^^^^^^^^^
  File "C:\Users\danil\AIdocAssistant\venv\Lib\site-packages\flask\app.py", line 1486, in full_dispatch_request
    rv = self.handle_user_exception(e)
         ^^^^^^^^^^^^^^^^^^^^^^^^^^^^^
  File "C:\Users\danil\AIdocAssistant\venv\Lib\site-packages\flask\app.py", line 1484, in full_dispatch_request
    rv = self.dispatch_request()
         ^^^^^^^^^^^^^^^^^^^^^^^
  File "C:\Users\danil\AIdocAssistant\venv\Lib\site-packages\flask\app.py", line 1469, in dispatch_request
    return self.ensure_sync(self.view_functions[rule.endpoint])(**view_args)
           ^^^^^^^^^^^^^^^^^^^^^^^^^^^^^^^^^^^^^^^^^^^^^^^^^^^^^^^^^^^^^^^^^
  File "C:\Users\danil\AIdocAssistant\venv\Lib\site-packages\flask_login\utils.py", line 284, in decorated_view
    elif not current_user.is_authenticated:
             ^^^^^^^^^^^^^^^^^^^^^^^^^^^^^
  File "C:\Users\danil\AIdocAssistant\venv\Lib\site-packages\werkzeug\local.py", line 311, in __get__
    obj = instance._get_current_object()
          ^^^^^^^^^^^^^^^^^^^^^^^^^^^^^^
  File "C:\Users\danil\AIdocAssistant\venv\Lib\site-packages\werkzeug\local.py", line 515, in _get_current_object
    return get_name(local())
                    ^^^^^^^
  File "C:\Users\danil\AIdocAssistant\venv\Lib\site-packages\flask_login\utils.py", line 25, in <lambda>
    current_user = LocalProxy(lambda: _get_user())
                                      ^^^^^^^^^^^
  File "C:\Users\danil\AIdocAssistant\venv\Lib\site-packages\flask_login\utils.py", line 372, in _get_user
    current_app.login_manager._load_user()
  File "C:\Users\danil\AIdocAssistant\venv\Lib\site-packages\flask_login\login_manager.py", line 364, in _load_user
    user = self._user_callback(user_id)
           ^^^^^^^^^^^^^^^^^^^^^^^^^^^^
  File "C:\Users\danil\AIdocAssistant\web\app\models.py", line 36, in load_user
    return User.query.get(int(id))
           ^^^^^^^^^^
  File "C:\Users\danil\AIdocAssistant\venv\Lib\site-packages\flask_sqlalchemy\model.py", line 22, in __get__
    return cls.query_class(
           ^^^^^^^^^^^^^^^^
  File "C:\Users\danil\AIdocAssistant\venv\Lib\site-packages\sqlalchemy\orm\query.py", line 276, in __init__
    self._set_entities(entities)
  File "C:\Users\danil\AIdocAssistant\venv\Lib\site-packages\sqlalchemy\orm\query.py", line 288, in _set_entities
    self._raw_columns = [
                        ^
  File "C:\Users\danil\AIdocAssistant\venv\Lib\site-packages\sqlalchemy\orm\query.py", line 289, in <listcomp>
    coercions.expect(
  File "C:\Users\danil\AIdocAssistant\venv\Lib\site-packages\sqlalchemy\sql\coercions.py", line 388, in expect
    insp._post_inspect
  File "C:\Users\danil\AIdocAssistant\venv\Lib\site-packages\sqlalchemy\util\langhelpers.py", line 1257, in __get__
    obj.__dict__[self.__name__] = result = self.fget(obj)
                                           ^^^^^^^^^^^^^^
  File "C:\Users\danil\AIdocAssistant\venv\Lib\site-packages\sqlalchemy\orm\mapper.py", line 2724, in _post_inspect
    self._check_configure()
  File "C:\Users\danil\AIdocAssistant\venv\Lib\site-packages\sqlalchemy\orm\mapper.py", line 2401, in _check_configure
    _configure_registries({self.registry}, cascade=True)
  File "C:\Users\danil\AIdocAssistant\venv\Lib\site-packages\sqlalchemy\orm\mapper.py", line 4214, in _configure_registries
    _do_configure_registries(registries, cascade)
  File "C:\Users\danil\AIdocAssistant\venv\Lib\site-packages\sqlalchemy\orm\mapper.py", line 4255, in _do_configure_registries
    mapper._post_configure_properties()
  File "C:\Users\danil\AIdocAssistant\venv\Lib\site-packages\sqlalchemy\orm\mapper.py", line 2418, in _post_configure_properties
    prop.init()
  File "C:\Users\danil\AIdocAssistant\venv\Lib\site-packages\sqlalchemy\orm\interfaces.py", line 589, in init
    self.do_init()
  File "C:\Users\danil\AIdocAssistant\venv\Lib\site-packages\sqlalchemy\orm\relationships.py", line 1658, in do_init
    self._setup_join_conditions()
  File "C:\Users\danil\AIdocAssistant\venv\Lib\site-packages\sqlalchemy\orm\relationships.py", line 1898, in _setup_join_conditions
    self._join_condition = jc = JoinCondition(
                                ^^^^^^^^^^^^^^
  File "C:\Users\danil\AIdocAssistant\venv\Lib\site-packages\sqlalchemy\orm\relationships.py", line 2324, in __init__
    self._determine_joins()
  File "C:\Users\danil\AIdocAssistant\venv\Lib\site-packages\sqlalchemy\orm\relationships.py", line 2458, in _determine_joins
    raise sa_exc.NoForeignKeysError(
sqlalchemy.exc.NoForeignKeysError: Could not determine join condition between parent/child tables on relationship DocumentApp.blocks - there are no foreign keys linking these tables.  Ensure that referencing columns are associated with a ForeignKey or ForeignKeyConstraint, or specify a 'primaryjoin' expression.
2025-04-07 13:07:07,635 INFO: NIR Assistant startup [in C:\Users\danil\AIdocAssistant\web\app\__init__.py:72]
2025-04-07 13:09:29,351 INFO: NIR Assistant startup [in C:\Users\danil\AIdocAssistant\web\app\__init__.py:72]
2025-04-07 13:11:24,355 INFO: NIR Assistant startup [in C:\Users\danil\AIdocAssistant\web\app\__init__.py:72]
2025-04-07 13:11:41,536 INFO: NIR Assistant startup [in C:\Users\danil\AIdocAssistant\web\app\__init__.py:72]
2025-04-08 14:39:35,765 INFO: NIR Assistant startup [in C:\Users\danil\AIdocAssistant\web\app\__init__.py:81]
